<?xml version="1.0" encoding="UTF-8"?>
<!-- Generated by org.testng.reporters.JUnitReportReporter -->
<testsuite hostname="RPC150" name="com.objectfrontier.training.java.webservices.test.PersonServiceTest" tests="1" failures="1" timestamp="23 Nov 2018 07:12:45 GMT" time="0.874" errors="0">
  <testcase name="testCreate_positive" time="0.874" classname="com.objectfrontier.training.java.webservices.test.PersonServiceTest">
    <failure type="java.lang.AssertionError" message=" expected:&lt;1&gt; but was:&lt;com.objectfrontier.training.java.webservices.service.AppException: com.fasterxml.jackson.databind.JsonMappingException: No content to map due to end-of-input
 at [Source: ; line: 1, column: 0]&gt;">
      <![CDATA[java.lang.AssertionError:  expected:<1> but was:<com.objectfrontier.training.java.webservices.service.AppException: com.fasterxml.jackson.databind.JsonMappingException: No content to map due to end-of-input
 at [Source: ; line: 1, column: 0]>
	at org.testng.Assert.fail(Assert.java:94)
	at com.objectfrontier.training.java.webservices.test.PersonServiceTest.testCreate_positive(PersonServiceTest.java:88)
	at sun.reflect.NativeMethodAccessorImpl.invoke0(Native Method)
	at sun.reflect.NativeMethodAccessorImpl.invoke(NativeMethodAccessorImpl.java:62)
	at sun.reflect.DelegatingMethodAccessorImpl.invoke(DelegatingMethodAccessorImpl.java:43)
	at java.lang.reflect.Method.invoke(Method.java:498)
	at org.testng.internal.MethodInvocationHelper.invokeMethod(MethodInvocationHelper.java:86)
	at org.testng.internal.Invoker.invokeMethod(Invoker.java:645)
	at org.testng.internal.Invoker.invokeTestMethod(Invoker.java:822)
	at org.testng.internal.Invoker.invokeTestMethods(Invoker.java:1130)
	at org.testng.internal.TestMethodWorker.invokeTestMethods(TestMethodWorker.java:129)
	at org.testng.internal.TestMethodWorker.run(TestMethodWorker.java:112)
	at org.testng.TestRunner.privateRun(TestRunner.java:782)
	at org.testng.TestRunner.run(TestRunner.java:632)
	at org.testng.SuiteRunner.runTest(SuiteRunner.java:366)
	at org.testng.SuiteRunner.runSequentially(SuiteRunner.java:361)
	at org.testng.SuiteRunner.privateRun(SuiteRunner.java:319)
	at org.testng.SuiteRunner.run(SuiteRunner.java:268)
	at org.testng.SuiteRunnerWorker.runSuite(SuiteRunnerWorker.java:52)
	at org.testng.SuiteRunnerWorker.run(SuiteRunnerWorker.java:86)
	at org.testng.TestNG.runSuitesSequentially(TestNG.java:1244)
	at org.testng.TestNG.runSuitesLocally(TestNG.java:1169)
	at org.testng.TestNG.run(TestNG.java:1064)
	at org.testng.remote.AbstractRemoteTestNG.run(AbstractRemoteTestNG.java:114)
	at org.testng.remote.RemoteTestNG.initAndRun(RemoteTestNG.java:251)
	at org.testng.remote.RemoteTestNG.main(RemoteTestNG.java:77)
]]>
    </failure>
  </testcase> <!-- testCreate_positive -->
</testsuite> <!-- com.objectfrontier.training.java.webservices.test.PersonServiceTest -->
